2024-03-25 15:12:24,215 INFO    StreamThr :52500 [internal.py:wandb_internal():86] W&B internal server running at pid: 52500, started at: 2024-03-25 15:12:24.214702
2024-03-25 15:12:24,217 DEBUG   HandlerThread:52500 [handler.py:handle_request():146] handle_request: status
2024-03-25 15:12:24,231 INFO    WriterThread:52500 [datastore.py:open_for_write():87] open: C:\Users\nks23\python310\traffic_signal_control\traffic_light_control\traffic_light_control_DQN-master\wandb\run-20240325_151224-e85dsgx1\run-e85dsgx1.wandb
2024-03-25 15:12:24,231 DEBUG   SenderThread:52500 [sender.py:send():378] send: header
2024-03-25 15:12:24,233 DEBUG   SenderThread:52500 [sender.py:send():378] send: run
2024-03-25 15:12:24,905 ERROR   SenderThread:52500 [internal_api.py:execute():373] 404 response executing GraphQL.
2024-03-25 15:12:24,905 ERROR   SenderThread:52500 [internal_api.py:execute():374] {"errors":[{"message":"project not found","path":["upsertBucket"]}],"data":{"upsertBucket":null}}
2024-03-25 15:12:24,916 ERROR   SenderThread:52500 [sender.py:send_run():950] It appears that you do not have permission to access the requested resource. Please reach out to the project owner to grant you access. If you have the correct permissions, verify that there are no issues with your networking setup.(Error 404: Not Found)
Traceback (most recent call last):
  File "C:\Users\nks23\AppData\Local\Programs\Python\Python310\lib\site-packages\wandb\sdk\lib\retry.py", line 131, in __call__
    result = self._call_fn(*args, **kwargs)
  File "C:\Users\nks23\AppData\Local\Programs\Python\Python310\lib\site-packages\wandb\sdk\internal\internal_api.py", line 369, in execute
    return self.client.execute(*args, **kwargs)  # type: ignore
  File "C:\Users\nks23\AppData\Local\Programs\Python\Python310\lib\site-packages\wandb\vendor\gql-0.2.0\wandb_gql\client.py", line 52, in execute
    result = self._get_result(document, *args, **kwargs)
  File "C:\Users\nks23\AppData\Local\Programs\Python\Python310\lib\site-packages\wandb\vendor\gql-0.2.0\wandb_gql\client.py", line 60, in _get_result
    return self.transport.execute(document, *args, **kwargs)
  File "C:\Users\nks23\AppData\Local\Programs\Python\Python310\lib\site-packages\wandb\sdk\lib\gql_request.py", line 59, in execute
    request.raise_for_status()
  File "C:\Users\nks23\AppData\Local\Programs\Python\Python310\lib\site-packages\requests\models.py", line 1021, in raise_for_status
    raise HTTPError(http_error_msg, response=self)
requests.exceptions.HTTPError: 404 Client Error: Not Found for url: https://api.wandb.ai/graphql

During handling of the above exception, another exception occurred:

Traceback (most recent call last):
  File "C:\Users\nks23\AppData\Local\Programs\Python\Python310\lib\site-packages\wandb\sdk\internal\sender.py", line 948, in send_run
    self._init_run(run, config_value_dict)
  File "C:\Users\nks23\AppData\Local\Programs\Python\Python310\lib\site-packages\wandb\sdk\internal\sender.py", line 990, in _init_run
    server_run, inserted, server_messages = self._api.upsert_run(
  File "C:\Users\nks23\AppData\Local\Programs\Python\Python310\lib\site-packages\wandb\apis\normalize.py", line 73, in wrapper
    raise err
  File "C:\Users\nks23\AppData\Local\Programs\Python\Python310\lib\site-packages\wandb\apis\normalize.py", line 41, in wrapper
    return func(*args, **kwargs)
  File "C:\Users\nks23\AppData\Local\Programs\Python\Python310\lib\site-packages\wandb\sdk\internal\internal_api.py", line 2216, in upsert_run
    response = self.gql(
  File "C:\Users\nks23\AppData\Local\Programs\Python\Python310\lib\site-packages\wandb\sdk\internal\internal_api.py", line 341, in gql
    ret = self._retry_gql(
  File "C:\Users\nks23\AppData\Local\Programs\Python\Python310\lib\site-packages\wandb\sdk\lib\retry.py", line 147, in __call__
    retry_timedelta_triggered = check_retry_fn(e)
  File "C:\Users\nks23\AppData\Local\Programs\Python\Python310\lib\site-packages\wandb\util.py", line 968, in check_retry_fn
    return fallback_retry_fn(e)
  File "C:\Users\nks23\AppData\Local\Programs\Python\Python310\lib\site-packages\wandb\util.py", line 910, in no_retry_auth
    raise CommError(
wandb.errors.CommError: It appears that you do not have permission to access the requested resource. Please reach out to the project owner to grant you access. If you have the correct permissions, verify that there are no issues with your networking setup.(Error 404: Not Found)
2024-03-25 15:12:25,276 DEBUG   HandlerThread:52500 [handler.py:handle_request():146] handle_request: shutdown
2024-03-25 15:12:25,276 INFO    HandlerThread:52500 [handler.py:finish():869] shutting down handler
2024-03-25 15:12:25,951 INFO    SenderThread:52500 [sender.py:finish():1521] shutting down sender
2024-03-25 15:12:26,251 INFO    WriterThread:52500 [datastore.py:close():296] close: C:\Users\nks23\python310\traffic_signal_control\traffic_light_control\traffic_light_control_DQN-master\wandb\run-20240325_151224-e85dsgx1\run-e85dsgx1.wandb
